<?xml version="1.0"?>
<robot xmlns:xacro="http://www.ros.org/wiki/xacro" name="crazyflie">

  <link name="map"/>
  <link name="crazyflie/odom"/> 
  <link name="crazyflie/base_footprint"/>

  <!-- Crazyflie body macro -->
  <xacro:macro name="base_link" params="mesh_package mass box_size_x box_size_y box_size_z">
    <link name="crazyflie/body">
      <!-- Inertial properties -->
      <inertial>
        <origin xyz="0 0 0.017425" rpy="0 0 0"/>
        <mass value="${mass}"/>
        <inertia 
          ixx="1.6571710e-05" iyy="1.6655602e-05" izz="2.9261652e-05"
          ixy="8.30806e-07" ixz="7.18277e-07" iyz="1.800197e-06"/>
      </inertial>

      <!-- Collision geometry -->
      <collision name="body_collision">
        <origin xyz="0 0 0.017425" rpy="0 0 0"/>
        <geometry>
          <box size="${box_size_x} ${box_size_y} ${box_size_z}"/>
        </geometry>
      </collision>

      <!-- Visual geometry -->
      <visual name="body_visual">
        <origin xyz="0 0 0.017425" rpy="0 0 0"/>
        <geometry>
          <mesh filename="file://$(find crazyflie_description)/meshes/collada_files/cf2_assembly.dae"/>
        </geometry>
      </visual>
    </link>
  </xacro:macro>

  <!-- Propeller macro -->
  <xacro:macro name="crazyflie_prop" params="prop_name mesh_package mass mesh_file">
    <link name="crazyflie/${prop_name}">
      <inertial>
        <mass value="${mass}"/>
        <inertia ixx="8.33333e-09" iyy="1.08333e-07" izz="1.13333e-07" ixy="0.0" ixz="0.0" iyz="0.0"/>
      </inertial>

      <visual>
        <origin xyz="0 0 0" rpy="0 0 0"/>
        <geometry>
          <mesh filename="file://$(find crazyflie_description)/meshes/collada_files/${mesh_file}"/>
        </geometry>
      </visual>

      <collision>
        <origin xyz="0 0 0" rpy="0 0 0"/>
        <geometry>
          <mesh filename="file://$(find crazyflie_description)/meshes/collada_files/${mesh_file}"/>
        </geometry>
      </collision>
    </link>
  </xacro:macro>

  <!-- Motor plugin parameters as xacro properties -->
  <xacro:property name="robot_ns" value="crazyflie"/>
  <xacro:property name="max_rot_velocity" value="2618"/>
  <xacro:property name="motor_constant" value="1.28192e-08"/>
  <xacro:property name="moment_constant" value="0.005964552"/>
  <xacro:property name="rotor_drag_coefficient" value="8.06428e-05"/>
  <xacro:property name="rolling_moment_coefficient" value="0.0000001"/>
  <xacro:property name="rotor_velocity_slowdown_sim" value="20"/>

  <!-- Multicopter Velocity Control Plugin Parameters -->
  <xacro:property name="control_command_topic" value="gazebo/command/twist"/>
  <xacro:property name="control_enable_topic" value="enable"/>
  <xacro:property name="control_velocity_gain" value="1.25 1.25 0.2425"/>
  <xacro:property name="control_attitude_gain" value="0.02 0.02 0.02"/>
  <xacro:property name="control_angular_rate_gain" value="0.005 0.005 0.005"/>
  <xacro:property name="control_force_constant" value="1.28192e-08"/>
  <xacro:property name="control_moment_constant" value="0.005964552"/>

  <!-- Instantiate body -->
  <xacro:base_link 
    mesh_package="crazyflie_description" 
    mass="0.025" 
    box_size_x="0.10" 
    box_size_y="0.10" 
    box_size_z="0.03485"/>

  <!-- Instantiate propellers -->
  <xacro:crazyflie_prop prop_name="m1_prop" mesh_package="crazyflie_description" mass="0.0008" mesh_file="ccw_prop.dae"/>
  <xacro:crazyflie_prop prop_name="m2_prop" mesh_package="crazyflie_description" mass="0.0008" mesh_file="cw_prop.dae"/>
  <xacro:crazyflie_prop prop_name="m3_prop" mesh_package="crazyflie_description" mass="0.0008" mesh_file="ccw_prop.dae"/>
  <xacro:crazyflie_prop prop_name="m4_prop" mesh_package="crazyflie_description" mass="0.0008" mesh_file="cw_prop.dae"/>

  <joint name="map_to_odom" type="fixed">
    <parent link="map"/>
    <child link="crazyflie/odom"/>
    <origin xyz="0 0 0" rpy="0 0 0"/>
  </joint>

  <joint name="odom_to_base_footprint" type="fixed">
    <parent link="crazyflie/odom"/>
    <child link="crazyflie/base_footprint"/>
    <origin xyz="0 0 0" rpy="0 0 0"/>
  </joint>

  <joint name="base_footprint_to_body" type="fixed">
    <parent link="crazyflie/base_footprint"/>
    <child link="crazyflie/body"/>
    <origin xyz="0 0 0" rpy="0 0 0"/>
  </joint>


  <!-- Joints between body and props -->
  <joint name="crazyflie/m1_joint" type="continuous">
    <parent link="crazyflie/body"/>
    <child link="crazyflie/m1_prop"/>
    <origin xyz="0.031 -0.031 0.021" rpy="0 0 0"/>
    <axis xyz="0 0 1"/>
    <limit effort="1.0" velocity="120.0"/>
  </joint>

  <joint name="crazyflie/m2_joint" type="continuous">
    <parent link="crazyflie/body"/>
    <child link="crazyflie/m2_prop"/>
    <origin xyz="-0.031 -0.031 0.021" rpy="0 0 0"/>
    <axis xyz="0 0 1"/>
    <limit effort="1.0" velocity="120.0"/>
  </joint>

  <joint name="crazyflie/m3_joint" type="continuous">
    <parent link="crazyflie/body"/>
    <child link="crazyflie/m3_prop"/>
    <origin xyz="-0.031 0.031 0.021" rpy="0 0 0"/>
    <axis xyz="0 0 1"/>
    <limit effort="1.0" velocity="120.0"/>
  </joint>

  <joint name="crazyflie/m4_joint" type="continuous">
    <parent link="crazyflie/body"/>
    <child link="crazyflie/m4_prop"/>
    <origin xyz="0.031 0.031 0.021" rpy="0 0 0"/>
    <axis xyz="0 0 1"/>
    <limit effort="1.0" velocity="120.0"/>
  </joint>
</robot>
